2025-03-10 10:39:28,030 INFO    MainThread:4240 [wandb_setup.py:_flush():67] Current SDK version is 0.19.8
2025-03-10 10:39:28,030 INFO    MainThread:4240 [wandb_setup.py:_flush():67] Configure stats pid to 4240
2025-03-10 10:39:28,030 INFO    MainThread:4240 [wandb_setup.py:_flush():67] Loading settings from C:\Users\ANJALI VERMA\.config\wandb\settings
2025-03-10 10:39:28,030 INFO    MainThread:4240 [wandb_setup.py:_flush():67] Loading settings from K:\DA6401\da6401_assignment1\wandb\settings
2025-03-10 10:39:28,030 INFO    MainThread:4240 [wandb_setup.py:_flush():67] Loading settings from environment variables
2025-03-10 10:39:28,031 INFO    MainThread:4240 [wandb_init.py:setup_run_log_directory():647] Logging user logs to K:\DA6401\da6401_assignment1\wandb\run-20250310_103928-v8vuf6us\logs\debug.log
2025-03-10 10:39:28,031 INFO    MainThread:4240 [wandb_init.py:setup_run_log_directory():648] Logging internal logs to K:\DA6401\da6401_assignment1\wandb\run-20250310_103928-v8vuf6us\logs\debug-internal.log
2025-03-10 10:39:28,031 INFO    MainThread:4240 [wandb_init.py:init():761] calling init triggers
2025-03-10 10:39:28,031 INFO    MainThread:4240 [wandb_init.py:init():766] wandb.init called with sweep_config: {}
config: {'_wandb': {}}
2025-03-10 10:39:28,031 INFO    MainThread:4240 [wandb_init.py:init():784] starting backend
2025-03-10 10:39:28,031 INFO    MainThread:4240 [wandb_init.py:init():788] sending inform_init request
2025-03-10 10:39:28,040 INFO    MainThread:4240 [backend.py:_multiprocessing_setup():101] multiprocessing start_methods=spawn, using: spawn
2025-03-10 10:39:28,040 INFO    MainThread:4240 [wandb_init.py:init():798] backend started and connected
2025-03-10 10:39:28,042 INFO    MainThread:4240 [wandb_init.py:init():891] updated telemetry
2025-03-10 10:39:28,043 INFO    MainThread:4240 [wandb_init.py:init():915] communicating run to backend with 90.0 second timeout
2025-03-10 10:39:28,463 ERROR   MainThread:4240 [wandb_init.py:init():1478] error in wandb.init()
Traceback (most recent call last):
  File "C:\Users\ANJALI VERMA\anaconda3\envs\dl\lib\site-packages\wandb\sdk\wandb_init.py", line 1468, in init
    return wi.init(run_settings, run_config)
  File "C:\Users\ANJALI VERMA\anaconda3\envs\dl\lib\site-packages\wandb\sdk\wandb_init.py", line 963, in init
    raise error
wandb.errors.errors.CommError: failed to upsert bucket: returned error 404: {"data":{"upsertBucket":null},"errors":[{"message":"entity your_username not found during upsertBucket","path":["upsertBucket"]}]}
2025-03-10 10:39:29,472 INFO    MsgRouterThr:4240 [mailbox.py:close():129] Closing mailbox, abandoning 0 handles.
