
Training model with cross_entropy loss...
 Starting training with config: {}
Traceback (most recent call last):
  File "C:\Users\ANJALI VERMA\anaconda3\envs\dl\lib\site-packages\wandb\sdk\wandb_config.py", line 165, in __getattr__
    return self.__getitem__(key)
  File "C:\Users\ANJALI VERMA\anaconda3\envs\dl\lib\site-packages\wandb\sdk\wandb_config.py", line 130, in __getitem__
    return self._items[key]
KeyError: 'dataset'

The above exception was the direct cause of the following exception:

Traceback (most recent call last):
  File "K:\DA6401\da6401_assignment1\cemse2.py", line 1054, in compare_losses
    history = train_model(args)
  File "K:\DA6401\da6401_assignment1\cemse2.py", line 811, in train_model
    (X_train, y_train_one_hot, y_train), (X_test, y_test_one_hot, y_test) = load_data(config.dataset)
  File "C:\Users\ANJALI VERMA\anaconda3\envs\dl\lib\site-packages\wandb\sdk\wandb_config.py", line 167, in __getattr__
    raise AttributeError(
AttributeError: <class 'wandb.sdk.wandb_config.Config'> object has no attribute 'dataset'
